<?xml version='1.0'?>
<robot name="dd_robot">

  <!-- Base Link -->
  <link name="base_link">
    <visual>
      <origin xyz="0 0 0" rpy="0 0 0" />
      <geometry>
          <box size="0.25 0.24 0.15"/>
      </geometry>
    </visual>
    <!-- Base collision, mass and inertia -->
    <collision>
      <origin xyz="0 0 0" rpy="0 0 0" />
      <geometry>
          <box size="0.25 0.24 0.15"/>
      </geometry>
    </collision>
    <inertial>
      <mass value="7"/>
      <inertia ixx="0.049583" ixy="0.0" ixz="0.0" iyy="0.070058" iyz="0.0" izz="0.046725"/>
    </inertial>

    <!-- Caster -->
    <visual name="caster">
      <origin xyz="0.09 0 -0.075" rpy="0 0 0" />
      <geometry>
        <sphere radius="0.035" />
      </geometry>
    </visual>
    <!-- Caster collision, mass and inertia -->
    <collision>
      <origin xyz="0.09 0 -0.075" rpy="0 0 0" />
      <geometry>
        <sphere radius="0.035" />
      </geometry>
    </collision>
    <inertial>
      <mass value="0.3"/>
      <inertia ixx="0.000147" ixy="0.0" ixz="0.0" iyy="0.000147" iyz="0.0" izz="0.000147"/>
    </inertial>

  </link>


  <gazebo reference="base_link">
    <material>Gazebo/Red</material>
    <pose>0 0 3 0 0 0</pose>
  </gazebo>

  <!-- Right Wheel -->
  <link name="right_wheel">
    <visual>
      <origin xyz="0 0 0" rpy="1.570795 0 0" />
      <geometry>
          <cylinder length="0.02" radius="0.035" />
      </geometry>
    </visual>
    <!-- Right Wheel collision, mass and inertia -->
    <collision>
      <origin xyz="0 0 0" rpy="1.570795 0 0" />
      <geometry>
          <cylinder length="0.02" radius="0.035" />
      </geometry>
    </collision>
    <inertial>
      <mass value="0.2"/>
      <inertia ixx="0.000123" ixy="0.0" ixz="0.0" iyy="0.000068" iyz="0.0" izz="0.000068"/>
    </inertial>

  </link>

  <gazebo reference="right_wheel">
    <material>Gazebo/Black</material>
  </gazebo>

  <!-- Right Wheel joint -->
  <joint name="joint_right_wheel" type="continuous">
    <parent link="base_link"/>
    <child link="right_wheel"/>
    <origin xyz="-0.12 -0.13 -0.075" rpy="0 0 0" /> 
    <axis xyz="0 1 0" />
  </joint>

  <!-- Left Wheel -->
  <link name="left_wheel">
    <visual>
      <origin xyz="0 0 0" rpy="1.570795 0 0" />
      <geometry>
          <cylinder length="0.02" radius="0.035" />
      </geometry>
    </visual>
    <!-- Left Wheel collision, mass and inertia -->
    <collision>
      <origin xyz="0 0 0" rpy="1.570795 0 0" />
      <geometry>
          <cylinder length="0.02" radius="0.035" />
      </geometry>
    </collision>
    <inertial>
      <mass value="0.2"/>
      <inertia ixx="0.000123" ixy="0.0" ixz="0.0" iyy="0.000068" iyz="0.0" izz="0.000068"/>
    </inertial>
  </link>

  <gazebo reference="left_wheel">
    <material>Gazebo/Black</material>
  </gazebo>

  <!-- Left Wheel joint -->
  <joint name="joint_left_wheel" type="continuous">
    <parent link="base_link"/>
    <child link="left_wheel"/>
    <origin xyz="-0.12 0.13 -0.075" rpy="0 0 0" /> 
    <axis xyz="0 1 0" />
  </joint>

 <gazebo>
  <plugin name="differential_drive_controller" filename="libgazebo_ros_diff_drive.so">
    <alwaysOn>true</alwaysOn>
    <legacyMode>false</legacyMode>
    <updateRate>100</updateRate>
    <robotNamespace>/</robotNamespace>
    <leftJoint>joint_left_wheel</leftJoint>
    <rightJoint>joint_right_wheel</rightJoint>
    <wheelSeparation>0.26</wheelSeparation>
    <wheelDiameter>0.07</wheelDiameter>
    <torque>10</torque>
    <commandTopic>cmd_vel</commandTopic>
    <odometryTopic>odom_diffdrive</odometryTopic>
    <odometryFrame>odom</odometryFrame>
    <odometrySource>world</odometrySource>
    <publishTf>1</publishTf>
    <rosDebugLevel>na</rosDebugLevel>
    <wheelAcceleration>0</wheelAcceleration>
    <wheelTorque>2</wheelTorque>
    <robotBaseFrame>base_link</robotBaseFrame>
    <publishWheelTF>false</publishWheelTF>
    <publishWheelJointState>false</publishWheelJointState>
  </plugin>
</gazebo>

</robot>
